Workbook

Sheet 가이드
A1: Route-Fit 가게 조사 양식 (동구·동명동 중심)
A2: 구도심(동구)의 개별 가게·명소를 조사해 코스 추천 데이터로 쌓습니다. 동명동의 식당·카페를 가장 먼저, 그다음 충장로·ACC·금남로·대인시장 순으로 채우세요.
A4: 1. 시트 구성
A5: 가게정보 | B5: 가게 한 곳 = 한 줄. 2행은 안내이니 지우지 마세요. id(A열)는 고치지 마세요.
A6: 체크리스트 | B6: 광주다움·상권 연계성·체류 유도성의 수동 항목 8개를 O/X로 체크. 가게마다 팀원 2명 이상이 서로 보지 않고 각자 한 줄씩 씁니다.
A7: 작성 예시 | B7: 가상의 가게로 채운 예시. 형식만 참고하세요.
A8: 목록 | B8: 드롭다운과 태그 값 목록. 할 거리·분위기·시간·동행은 이 값만 쉼표로 적습니다.
A9: 2. 칸 색
A10: 진한 초록 머리글 (★) | B10: 필수. 비우면 시스템에 넣을 수 없습니다.
A11: 회청색 머리글 | B11: 선택. 아는 만큼만.
A12: 연한 파랑 머리글 [참고] | B12: 대표 메뉴·음식 종류·식사 시간대. 지금 시스템에는 저장 칸이 없지만, 식당 추천을 위해 미리 모아 둡니다.
A13: 회색 칸 | B13: 자동 또는 수정 금지.
A14: 3. 작성 규칙
A15: 추측하지 않기 | B15: 확인 못 한 값은 비워 두세요. 영업시간·가격은 출처(링크)와 조사일을 꼭 남깁니다.
A16: 시각 | B16: 24시간 HH:MM. 자정을 넘기면 25:00 (새벽 1시). 예: 11:00 / 25:00
A17: 휴무 요일 | B17: 월, 화, 수, 목, 금, 토, 일 중 쉼표로. 연중무휴면 비움.
A18: 1인 예상 지출 | B18: 메뉴 1개 + 음료 기준 대략의 값(원). 무료면 0.
A19: 한줄 소개 | B19: 개업 연도, 대표 메뉴 등 확인된 사실만. 홍보 문구·추측 금지.
A20: 위도·경도 | B20: 비워도 됩니다. 정확한 도로명 주소만 적어 주세요. 좌표는 장소 관리 화면에서 지도를 눌러 넣습니다.
A21: 4. 체크리스트
A22: O / X | B22: '맞다/아니다'를 사실로 확인합니다. 확인 방법은 체크리스트 시트 2행에 있습니다. 근거(링크·사진 파일명)를 적어 주세요.
A23: 자동 항목 | B23: 머무는 시간 60분 이상, 지출 0원 초과, 할 거리 2개 이상, 19시 이후 운영은 시스템이 계산하므로 적지 않습니다.
A24: 프랜차이즈 | B24: '프랜차이즈나 대기업 직영이 아니다'는 프랜차이즈가 아니면 O 입니다.
A26: 5. 진행 현황 (자동 계산)
A27: 항목 | B27: 현재 | C27: 목표 | D27: 비고
A28: 입력한 가게 수 | B28: =COUNTA(가게정보!$B$3:$B$122)
A29: 식당 | B29: =COUNTIF(가게정보!$C$3:$C$122,"식당") | C29: 20 | D29: 멘토링 메모: 동구 식당 20개 이상 (팀에서 확정)
A30: 카페·디저트 | B30: =COUNTIF(가게정보!$C$3:$C$122,"카페·디저트")
A31: 동구 가게 | B31: =COUNTIF(가게정보!$D$3:$D$122,"동구*")
A32: 동명동 가게 | B32: =COUNTIF(가게정보!$D$3:$D$122,"*동명동*") | D32: 동명동 중심 방향
A33: 체크리스트 작성 줄 수 | B33: =COUNTA(체크리스트!$C$3:$C$302) | C33: 10 | D33: 멘토링 메모: 체크리스트 10개 이상 (팀에서 확정, 가게×채점자 줄 수)
A35: 6. 다 채운 뒤
A36: 이 파일을 알려 주시면 데이터(JSON)로 바꿔 장소 관리 화면에서 확인할 수 있게 하고, 좌표와 태그를 점검합니다.

Sheet 가게정보
A1: id (수정 금지) | B1: ★가게 이름 | C1: ★유형 | D1: ★지역 | E1: ★도로명 주소 | F1: 위도 | G1: 경도 | H1: ★여는 시각 | I1: ★닫는 시각 | J1: 휴무 요일 | K1: ★머무는 시간(분) | L1: ★1인 예상 지출(원) | M1: 대표 메뉴·가격 [참고] | N1: 음식 종류 [참고] | O1: 식사 시간대 [참고] | P1: ★할 거리 | Q1: ★분위기 | R1: ★공간 | S1: 어울리는 시간 | T1: 어울리는 동행 | U1: 별칭 | V1: 한줄 소개 | W1: 조사자 | X1: 조사일 | Y1: 정보 출처 (링크·날짜) | Z1: 메모
A2: 자동 번호 | B2: 간판 이름 그대로 | C2: 목록에서 고르기 | D2: 예: 동구 동명동 | E2: 정확히. 좌표는 나중에 지도로 넣음 | F2: 몰라도 됨 | G2: 몰라도 됨 | H2: 24시간 HH:MM 예: 11:00 | I2: 자정 넘기면 25:00 | J2: 예: 월 / 월, 화 (연중무휴면 비움) | K2: 보통 머무는 시간 예: 60 | L2: 메뉴1+음료 기준. 무료는 0 | M2: 예: 된장찌개 9,000 / 제육 10,000 | N2: 식당·카페만 | O2: 점심/저녁 중 주로 가는 때 | P2: 목록 값을 쉼표로 예: 식사, 사진 | Q2: 목록 값을 쉼표로 | R2: 하나만 고르기 | S2: 쉼표로. 예: 저녁, 밤 | T2: 쉼표로. 예: 친구, 연인 | U2: 손님들이 부르는 다른 이름 (쉼표) | V2: 확인된 사실만 (개업 연도, 대표 메뉴 등). 홍보 문구·추측 금지 | W2: 이름 | X2: 예: 2026-10-20 | Y2: 영업시간·가격을 어디서 확인했는지
A3: store_001 | B3: 산수쌈밥 동명점 | C3: 식당 | D3: 동구 동명동 | E3: 광주광역시 동구 동계로 11 | H3: 10:30 | I3: 20:00 | J3: 일 | K3: 80 | L3: 9500 | M3: 우렁이 쌈밥 정식 10,000 / 혼밥정식 12,000 / 우렁이 비빔밥 9,000 | N3: 우렁이쌈밥,들깨탕 | P3: 식사 | Q3: 현대적 | R3: 실내 | S3: 오전, 오후, 저녁 | W3: Claude(웹 수집) | X3: 2026-10-21 | Y3: https://www.diningcode.com/profile.php?rid=6bbCBHAtq9Ml | Z3: 초안(웹 수집). 현장 미확인 / 추정 칸: 머무는 시간·1인 지출·태그·지역 / 라스트오더 19:30
A4: store_002 | B4: 동명사랑채 | C4: 식당 | D4: 동구 동명동 | E4: 광주광역시 동구 동계로9번길 2 | H4: 11:00 | I4: 22:00 | J4: 일 | K4: 80 | L4: 10500 | M4: 우렁강된장쌈밥 11,000 / 애호박찌개 10,000 | N4: 쌈밥,우렁 | P4: 식사 | Q4: 현대적 | R4: 실내 | S4: 오전, 오후, 저녁 | V4: 무료주차 | W4: Claude(웹 수집) | X4: 2026-10-21 | Y4: https://www.diningcode.com/profile.php?rid=ZzJVqaMYHG3M | Z4: 초안(웹 수집). 현장 미확인 / 추정 칸: 머무는 시간·1인 지출·태그·지역
A5: store_003 | B5: 이층집백반 | C5: 식당 | D5: 동구 동명동 | E5: 광주광역시 동구 백서로 153 2층 | H5: 11:30 | I5: 13:30 | J5: 토,일 | K5: 40 | L5: 9000 | M5: 점심 백반뷔페 9,000 | N5: 한식,백반 | P5: 식사 | Q5: 서민적 | R5: 실내 | S5: 오전, 오후 | V5: 점심 가정식 백반뷔페 | W5: Claude(웹 수집) | X5: 2026-10-21 | Y5: https://www.diningcode.com/profile.php?rid=UdTmtvrvt28Z | Z5: 초안(웹 수집). 현장 미확인 / 추정 칸: 머무는 시간·1인 지출·태그·지역 / 라스트오더 13:00
A6: store_004 | B6: 송경솥밥 | C6: 식당 | D6: 동구 동명동 | E6: 광주광역시 동구 동명로14번길 19-8 2층 | H6: 11:00 | I6: 21:00 | K6: 60 | L6: 15000 | M6: LA갈비솥밥 24,000 / 트러플 차돌버섯솥밥 14,000 / 냉이 돼지스테이크 솥밥 16,000 | N6: 한식,솥밥 | P6: 식사 | Q6: 현대적 | R6: 실내 | S6: 오전, 오후, 저녁 | W6: Claude(웹 수집) | X6: 2026-10-21 | Y6: https://www.diningcode.com/profile.php?rid=AzsEpSGMQzjq | Z6: 초안(웹 수집). 현장 미확인 / 추정 칸: 머무는 시간·1인 지출·태그·지역
A7: store_005 | B7: 올데이우동 동명점 | C7: 식당 | D7: 동구 동명동 | E7: 광주광역시 동구 동계천로 151-31 1층 | H7: 11:30 | I7: 20:30 | K7: 40 | L7: 12000 | M7: 붓가케 우동 9,000 / 우동돈까스 세트 15,000 | N7: 우동 | P7: 식사 | Q7: 현대적 | R7: 실내 | S7: 오전, 오후, 저녁 | V7: 자가제면 언급 | W7: Claude(웹 수집) | X7: 2026-10-21 | Y7: https://www.diningcode.com/profile.php?rid=JIpsbDuKo6Ox | Z7: 초안(웹 수집). 현장 미확인 / 추정 칸: 머무는 시간·1인 지출·태그·지역 / 라스트오더 20:00
A8: store_006 | B8: 첨단공원국밥 동명직영점 | C8: 식당 | D8: 동구 동명동 | E8: 광주광역시 동구 제봉로110번길 7 1층 | H8: 00:00 | I8: 24:00 | K8: 40 | L8: 22000 | M8: 풍성한 모듬국밥 11,000 / 막창 전골 33,000 | N8: 국밥,막창볶음 | P8: 식사 | Q8: 서민적 | R8: 실내 | S8: 오전, 오후, 저녁, 밤 | V8: 24시간 영업 | W8: Claude(웹 수집) | X8: 2026-10-21 | Y8: https://www.diningcode.com/profile.php?rid=Y1kAcu0837Ua | Z8: 초안(웹 수집). 현장 미확인 / 추정 칸: 머무는 시간·1인 지출·태그·지역
A9: store_007 | B9: 왕산식당 본점 | C9: 식당 | D9: 동구 동명동 | E9: 광주광역시 동구 동명로14번길 6-1 | H9: 11:30 | I9: 22:00 | K9: 60 | L9: 12000 | M9: 동파육덮밥 17,000 / 수란간짜장 12,000 / 소고기짬뽕 12,000 | N9: 중식 | P9: 식사 | Q9: 감성적 | R9: 실내 | S9: 오전, 오후, 저녁 | V9: 주택 개조 중식당 | W9: Claude(웹 수집) | X9: 2026-10-21 | Y9: https://www.diningcode.com/profile.php?rid=C7RCEVbvt0ao | Z9: 초안(웹 수집). 현장 미확인 / 추정 칸: 머무는 시간·1인 지출·태그·지역 / 브레이크타임 15:00-17:00 / 라스트오더 20:30
A10: store_008 | B10: 포카포카 | C10: 식당 | D10: 동구 동명동 | E10: 광주광역시 동구 동명로25번길 11 1층 | H10: 11:30 | I10: 21:00 | K10: 60 | L10: 16000 | M10: 아부리사케동 정식 16,000 / 함바그하이라이스 16,500 | N10: 일본가정식,돈카츠 | P10: 식사 | Q10: 현대적 | R10: 실내 | S10: 오전, 오후, 저녁 | V10: 주차불가 표기 | W10: Claude(웹 수집) | X10: 2026-10-21 | Y10: https://www.diningcode.com/profile.php?rid=taZBC197m0fj | Z10: 초안(웹 수집). 현장 미확인 / 추정 칸: 머무는 시간·1인 지출·태그·지역 / 브레이크타임 15:30-17:00 / 라스트오더 15:00,20:30 / 휴무 확인 필요(노동절·설·추석 당일)
A11: store_009 | B11: 카에돈 | C11: 식당 | D11: 동구 동명동 | E11: 광주광역시 동구 동계천로 143-26 101호 | H11: 11:30 | I11: 21:00 | K11: 60 | L11: 16500 | M11: 규카츠 18,000 / 상로스카츠 16,000 / 모듬카츠 17,000 | N11: 카츠 | P11: 식사 | Q11: 현대적 | R11: 실내 | S11: 오전, 오후, 저녁 | W11: Claude(웹 수집) | X11: 2026-10-21 | Y11: https://www.diningcode.com/profile.php?rid=LnwIGem0cX0w | Z11: 초안(웹 수집). 현장 미확인 / 추정 칸: 머무는 시간·1인 지출·태그·지역 / 브레이크타임 15:00-17:00 / 라스트오더 20:00 / 휴무 확인 필요(요일 미표시)
A12: store_010 | B12: 미노라멘 | C12: 식당 | D12: 동구 동명동 | E12: 광주광역시 동구 동계로10번길 14 1층 | H12: 11:30 | I12: 20:30 | K12: 40 | L12: 8000 | M12: 늘먹던걸로 11,000 / 챠-항 5,000 | N12: 라멘 | P12: 식사 | Q12: 현대적 | R12: 실내 | S12: 오전, 오후, 저녁 | W12: Claude(웹 수집) | X12: 2026-10-21 | Y12: https://www.diningcode.com/profile.php?rid=CNRXlAEZ9w0r | Z12: 초안(웹 수집). 현장 미확인 / 추정 칸: 머무는 시간·1인 지출·태그·지역 / 브레이크타임 15:00-17:00 / 라스트오더 14:30,20:00
A13: store_011 | B13: 토메이 스시 | C13: 식당 | D13: 동구 동명동 | E13: 광주광역시 동구 동계천로 155 | H13: 11:30 | I13: 22:00 | J13: 일 | K13: 60 | L13: 18000 | M13: 모듬사시미 32,000 / 토메이특초밥 20,000 / 연어불초밥 16,000 | N13: 초밥 | P13: 식사 | Q13: 현대적 | R13: 실내 | S13: 오전, 오후, 저녁 | W13: Claude(웹 수집) | X13: 2026-10-21 | Y13: https://www.diningcode.com/profile.php?rid=J8l2LgZyc1jl | Z13: 초안(웹 수집). 현장 미확인 / 추정 칸: 머무는 시간·1인 지출·태그·지역 / 브레이크타임 15:00-17:00 / 라스트오더 21:00
A14: store_012 | B14: 저스트텐동 동리단길점 | C14: 식당 | D14: 동구 동명동 | E14: 광주광역시 동구 장동로 23-22 1층 | H14: 11:30 | I14: 21:00 | K14: 40 | L14: 15000 | M14: 스페셜텐동 17,900 / 저스트텐동 11,900 | N14: 텐동 | P14: 식사 | Q14: 현대적 | R14: 실내 | S14: 오전, 오후, 저녁 | V14: 무료주차 표기 | W14: Claude(웹 수집) | X14: 2026-10-21 | Y14: https://www.diningcode.com/profile.php?rid=ogFxmCC5QVvN | Z14: 초안(웹 수집). 현장 미확인 / 추정 칸: 머무는 시간·1인 지출·태그·지역 / 브레이크타임 15:00-17:00 / 라스트오더 14:30,20:30 / 휴무 확인 필요(확인필요(블로그 월요일 언급))
A15: store_013 | B15: 백식 | C15: 식당 | D15: 동구 동명동 | E15: 광주광역시 동구 동명로20번길 17-6 | H15: 10:50 | I15: 21:00 | K15: 60 | L15: 24500 | M15: 백식 사시미 정식 23,000 / 특선 사시미 정식 29,000 / 장어 덮밥 정식 26,000 | N15: 일식 | P15: 식사 | Q15: 현대적 | R15: 실내 | S15: 오전, 오후, 저녁 | V15: 예약가능 | W15: Claude(웹 수집) | X15: 2026-10-21 | Y15: https://www.diningcode.com/profile.php?rid=KAFfsG2dyxU9 | Z15: 초안(웹 수집). 현장 미확인 / 추정 칸: 머무는 시간·1인 지출·태그·지역 / 라스트오더 20:00
A16: store_014 | B16: 카키노키 | C16: 식당 | D16: 동구 동명동 | E16: 광주광역시 동구 장동로 23-57 1층 | H16: 11:30 | I16: 21:00 | K16: 60 | L16: 14500 | M16: 숯불부타동 정식 13,000 / 모듬카츠동 정식 16,000 / 들기름 막국수 정식 16,000 | N16: 일본가정식 | P16: 식사 | Q16: 현대적 | R16: 실내 | S16: 오전, 오후, 저녁 | W16: Claude(웹 수집) | X16: 2026-10-21 | Y16: https://www.diningcode.com/profile.php?rid=m0tTLUydeeLd | Z16: 초안(웹 수집). 현장 미확인 / 추정 칸: 머무는 시간·1인 지출·태그·지역 / 라스트오더 20:30
A17: store_015 | B17: 뽁식당 동명동점 | C17: 식당 | D17: 동구 동명동 | E17: 광주광역시 동구 동계천로 126-5 1층 | H17: 11:30 | I17: 21:00 | K17: 60 | L17: 9500 | M17: 뽁식당 혼밥세트 10,400 / 피자 세트 33,700 / 오감베로 파스타 8,900 | N17: 파스타,양식 | P17: 식사 | Q17: 현대적 | R17: 실내 | S17: 오전, 오후, 저녁 | V17: 무료주차 | W17: Claude(웹 수집) | X17: 2026-10-21 | Y17: https://www.diningcode.com/profile.php?rid=ot4UCmT6Tq0n | Z17: 초안(웹 수집). 현장 미확인 / 추정 칸: 머무는 시간·1인 지출·태그·지역 / 브레이크타임 15:00-17:00 / 라스트오더 20:10
A18: store_016 | B18: 라그로쏘 | C18: 식당 | D18: 동구 충장로 | E18: 광주광역시 동구 중앙로252번길 11 1,2층 | H18: 11:30 | I18: 22:00 | J18: 화,수 | K18: 60 | L18: 16500 | M18: 마르게리타 D.O.P 15,000 / 비스큐 스파게티니 18,000 | N18: 피자,파스타 | P18: 식사 | Q18: 현대적 | R18: 실내 | S18: 오전, 오후, 저녁 | V18: 화덕 피자 | W18: Claude(웹 수집) | X18: 2026-10-21 | Y18: https://www.diningcode.com/profile.php?rid=ANZzYl13xxDq | Z18: 초안(웹 수집). 현장 미확인 / 추정 칸: 머무는 시간·1인 지출·태그·지역 / 영업시간 참고: 블로그 기준 / 브레이크타임 15:30-17:00(블로그) / 라스트오더 14:30,21:00 / 휴무 근거: 블로그
A19: store_017 | B19: 900달러 | C19: 식당 | D19: 동구 동명동 | E19: 광주광역시 동구 동계천로 103-2 | H19: 11:30 | I19: 23:00 | K19: 60 | L19: 23500 | M19: 하프/하프 피자 24,500 / 고구마피자 24,000 / 페퍼로니피자 23,000 | N19: 피자 | P19: 식사 | Q19: 현대적 | R19: 실내 | S19: 오전, 오후, 저녁, 밤 | V19: 전용주차장 없음 | W19: Claude(웹 수집) | X19: 2026-10-21 | Y19: https://www.diningcode.com/profile.php?rid=WINBF2d9a4jP | Z19: 초안(웹 수집). 현장 미확인 / 추정 칸: 머무는 시간·1인 지출·태그·지역 / 라스트오더 22:00 / 휴무 확인 필요(확인필요(블로그 수요일))
A20: store_018 | B20: 르 자민 | C20: 식당 | D20: 동구 동명동 | E20: 광주광역시 동구 장동로 13 2층 | H20: 11:30 | I20: 21:30 | K20: 80 | L20: 50500 | M20: 티본 스테이크 79,000 / 부채 스테이크 36,000 / 본인뉴욕 스테이크 65,000 | N20: 스테이크 | P20: 식사 | Q20: 현대적 | R20: 실내 | S20: 오전, 오후, 저녁 | V20: 예약가능,무료주차 | W20: Claude(웹 수집) | X20: 2026-10-21 | Y20: https://www.diningcode.com/profile.php?rid=bmNBhUBYABLx | Z20: 초안(웹 수집). 현장 미확인 / 추정 칸: 머무는 시간·1인 지출·태그·지역 / 브레이크타임 15:00-17:00 / 라스트오더 20:30
A21: store_019 | B21: 사보타지 | C21: 식당 | D21: 동구 동명동 | E21: 광주광역시 동구 동계천로95번길 12 | H21: 09:00 | I21: 15:00 | K21: 60 | L21: 13000 | M21: 팬케이크 플레이트 12,900 / 와플 플레이트 12,900 | N21: 브런치 | P21: 식사 | Q21: 현대적 | R21: 실내 | S21: 오전, 오후 | V21: 미국 가정식 콘셉트 | W21: Claude(웹 수집) | X21: 2026-10-21 | Y21: https://www.diningcode.com/profile.php?rid=yvEk745bQ5uI | Z21: 초안(웹 수집). 현장 미확인 / 추정 칸: 머무는 시간·1인 지출·태그·지역 / 영업시간 참고: 평일 기준. 주말 09:00-16:00 / 라스트오더 평일14:30 주말15:30
A22: store_020 | B22: 미미원 | C22: 식당 | D22: 동구 동명동 | E22: 광주 동구 백서로 218 | H22: 11:30 | I22: 21:30 | K22: 60 | L22: 16500 | M22: 육전 29,000 / 낙지전 28,000 / 키조개전 27,000 / 매생이떡국 6,000 | N22: 육전 | P22: 식사 | Q22: 현대적 | R22: 실내 | S22: 오전, 오후, 저녁 | V22: 재료소진시 조기마감 | W22: Claude(웹 수집) | X22: 2026-10-21 | Y22: https://forourtour.com/%EB%8F%99%EB%AA%85%EB%8F%99-%EB%A7%9B%EC%A7%91/ | Z22: 초안(웹 수집). 현장 미확인 / 추정 칸: 머무는 시간·1인 지출·태그·지역 / 브레이크타임 15:00-17:00 / 라스트오더 14:00
A23: store_021 | B23: 규슈 | C23: 식당 | D23: 동구 동명동 | E23: 광주 동구 동명로 47-3 | H23: 11:30 | I23: 21:00 | K23: 80 | L23: 5000 | M23: 샤브 2인 세트(호주산) 29,800 / 유부주머니 5,000 | N23: 샤브샤브 | P23: 식사 | Q23: 현대적 | R23: 실내 | S23: 오전, 오후, 저녁 | V23: 하루 100인분 한정 | W23: Claude(웹 수집) | X23: 2026-10-21 | Y23: https://forourtour.com/%EB%8F%99%EB%AA%85%EB%8F%99-%EB%A7%9B%EC%A7%91/ | Z23: 초안(웹 수집). 현장 미확인 / 추정 칸: 머무는 시간·1인 지출·태그·지역
A24: store_022 | B24: 목하식당 | C24: 식당 | D24: 동구 동명동 | E24: 광주 동구 동명로25번길 6 1층 | H24: 11:30 | I24: 21:00 | K24: 60 | L24: 9000 | M24: 오리지널 오믈렛 10,500 / 새우 로제 파스타 15,000 / 가츠 산도 7,000 | N24: 일식(오믈렛,파스타) | P24: 식사 | Q24: 현대적 | R24: 실내 | S24: 오전, 오후, 저녁 | W24: Claude(웹 수집) | X24: 2026-10-21 | Y24: https://forourtour.com/%EB%8F%99%EB%AA%85%EB%8F%99-%EB%A7%9B%EC%A7%91/ | Z24: 초안(웹 수집). 현장 미확인 / 추정 칸: 머무는 시간·1인 지출·태그·지역 / 브레이크타임 15:10-17:00 / 라스트오더 14:30,20:00
A25: store_023 | B25: 틸트틸트 | C25: 식당 | D25: 동구 동명동 | E25: 광주 동구 동계로15번길 22 1층 | H25: 11:30 | I25: 21:00 | K25: 60 | L25: 19500 | M25: 우니&단새우 파스타 22,000 / 땡초 크림 트러플 리가토니 17,000 | N25: 양식 브런치 | P25: 식사 | Q25: 현대적 | R25: 실내 | S25: 오전, 오후, 저녁 | W25: Claude(웹 수집) | X25: 2026-10-21 | Y25: https://forourtour.com/%EB%8F%99%EB%AA%85%EB%8F%99-%EB%A7%9B%EC%A7%91/ | Z25: 초안(웹 수집). 현장 미확인 / 추정 칸: 머무는 시간·1인 지출·태그·지역 / 브레이크타임 16:00-17:00 / 라스트오더 20:30
A26: store_024 | B26: 정희 | C26: 식당 | D26: 동구 동명동 | E26: 광주 동구 동명로20번길 20 1층 | H26: 11:30 | I26: 21:00 | K26: 60 | L26: 12000 | M26: 고사리 크림 수제비 12,900 / 한우 지짐밥 13,900 / 강된장케일쌈밥 10,900 | N26: 퓨전 한식 | P26: 식사 | Q26: 현대적 | R26: 실내 | S26: 오전, 오후, 저녁 | W26: Claude(웹 수집) | X26: 2026-10-21 | Y26: https://forourtour.com/%EB%8F%99%EB%AA%85%EB%8F%99-%EB%A7%9B%EC%A7%91/ | Z26: 초안(웹 수집). 현장 미확인 / 추정 칸: 머무는 시간·1인 지출·태그·지역 / 브레이크타임 15:00-17:00 / 라스트오더 20:30
A27: store_025 | B27: 한식경 | C27: 식당 | D27: 동구 동명동 | E27: 광주 동구 동명로25번길 6-1 | H27: 11:30 | I27: 21:00 | K27: 60 | L27: 16000 | M27: 아롱사태 크림리조또 17,000 / 곰탕 크림 파스타 15,000 | N27: 퓨전 양식 | P27: 식사 | Q27: 감성적 | R27: 실내 | S27: 오전, 오후, 저녁 | V27: 한옥 레스토랑 분위기 | W27: Claude(웹 수집) | X27: 2026-10-21 | Y27: https://forourtour.com/%EB%8F%99%EB%AA%85%EB%8F%99-%EB%A7%9B%EC%A7%91/ | Z27: 초안(웹 수집). 현장 미확인 / 추정 칸: 머무는 시간·1인 지출·태그·지역 / 브레이크타임 15:30-17:00 / 라스트오더 20:15
A28: store_026 | B28: 소바 쿄다이 | C28: 식당 | D28: 동구 동명동 | E28: 광주 동구 동계천로 135-3 | H28: 11:30 | I28: 21:00 | K28: 60 | L28: 11000 | M28: 쿄다이 마제소바 10,500 / 키마 카레소바 11,000 / 훈제고등어 냉소바 12,000 | N28: 마제소바 | P28: 식사 | Q28: 현대적 | R28: 실내 | S28: 오전, 오후, 저녁 | W28: Claude(웹 수집) | X28: 2026-10-21 | Y28: https://forourtour.com/%EB%8F%99%EB%AA%85%EB%8F%99-%EB%A7%9B%EC%A7%91/ | Z28: 초안(웹 수집). 현장 미확인 / 추정 칸: 머무는 시간·1인 지출·태그·지역 / 라스트오더 20:45
A29: store_027 | B29: 퀴비 | C29: 식당 | D29: 동구 동명동 | E29: 광주 동구 동명로20번길 1 | H29: 12:00 | I29: 21:00 | K29: 60 | L29: 17500 | M29: 바질 오일 파스타 18,000 / 로제 파스타 17,000 / 뇨끼 18,000 | N29: 이탈리안 | P29: 식사 | Q29: 현대적 | R29: 실내 | S29: 오후, 저녁 | V29: 화덕 피자 | W29: Claude(웹 수집) | X29: 2026-10-21 | Y29: https://forourtour.com/%EB%8F%99%EB%AA%85%EB%8F%99-%EB%A7%9B%EC%A7%91/ | Z29: 초안(웹 수집). 현장 미확인 / 추정 칸: 머무는 시간·1인 지출·태그·지역 / 브레이크타임 15:00-17:00 / 라스트오더 14:00,20:00
A30: store_028 | B30: 게더링 | C30: 식당 | D30: 동구 동명동 | E30: 광주 동구 동계천로 168 | H30: 11:00 | I30: 21:00 | J30: 월 | K30: 60 | L30: 14500 | M30: 씨푸드 찰리 17,000 / 스테이크 묵은지 오일 파스타 19,000 / 크로아상 에그 베네딕트 12,000 | N30: 브런치,파스타,피자 | P30: 식사 | Q30: 감성적 | R30: 실내외 | S30: 오전, 오후, 저녁 | V30: 40년 이상 된 주택 개조, 정원 | W30: Claude(웹 수집) | X30: 2026-10-21 | Y30: https://forourtour.com/%EB%8F%99%EB%AA%85%EB%8F%99-%EB%A7%9B%EC%A7%91/ | Z30: 초안(웹 수집). 현장 미확인 / 추정 칸: 머무는 시간·1인 지출·태그·지역 / 브레이크타임 15:00-17:00
A31: store_029 | B31: 분식집 | C31: 식당 | D31: 동구 동명동 | E31: 광주 동구 동계천로 143-5 1층 | H31: 11:30 | I31: 20:30 | K31: 40 | L31: 7500 | M31: 파튀김 떡볶이 6,500 / 상추튀김 8,500 / 마늘 탕수육 9,700 | N31: 분식 | P31: 식사 | Q31: 서민적 | R31: 실내 | S31: 오전, 오후, 저녁 | V31: 시즌별 신메뉴 | W31: Claude(웹 수집) | X31: 2026-10-21 | Y31: https://forourtour.com/%EB%8F%99%EB%AA%85%EB%8F%99-%EB%A7%9B%EC%A7%91/ | Z31: 초안(웹 수집). 현장 미확인 / 추정 칸: 머무는 시간·1인 지출·태그·지역 / 브레이크타임 15:00-17:00 / 라스트오더 14:30
A32: store_030 | B32: 채미원 | C32: 식당 | D32: 동구 동명동 | E32: 광주 동구 동계천로 167-7 1층 | H32: 11:30 | I32: 22:00 | J32: 일 | K32: 60 | M32: 주물럭 쌈밥·병어갈치조림·굴비구이(가격 없음) | N32: 한식 정식 | P32: 식사 | Q32: 현대적 | R32: 실내 | S32: 오전, 오후, 저녁 | V32: 화학조미료 없이 | W32: Claude(웹 수집) | X32: 2026-10-21 | Y32: https://v.daum.net/v/zCXt4I5rbs | Z32: 초안(웹 수집). 현장 미확인 / 추정 칸: 머무는 시간·1인 지출·태그·지역 / 브레이크타임 14:30-17:00 / 지출 추정 불가(메뉴 가격 없음) - 직접 입력
A33: store_031 | B33: 장독대 | C33: 식당 | D33: 동구 광산동 | E33: 광주 동구 문화전당로 43 3층 | H33: 11:00 | I33: 21:00 | K33: 80 | M33: 쌈밥 정식 등(가격 없음) | N33: 남도쌈밥 한식 | P33: 식사 | Q33: 현대적 | R33: 실내 | S33: 오전, 오후, 저녁 | V33: 반찬 셀프바 | W33: Claude(웹 수집) | X33: 2026-10-21 | Y33: https://v.daum.net/v/zCXt4I5rbs | Z33: 초안(웹 수집). 현장 미확인 / 추정 칸: 머무는 시간·1인 지출·태그·지역 / 지출 추정 불가(메뉴 가격 없음) - 직접 입력
A34: store_032 | B34: 가족회관 | C34: 식당 | D34: 동구 동명동 | E34: 광주 동구 동명로 50 | K34: 80 | M34: 한정식(가격 없음) | N34: 한정식 | P34: 식사 | Q34: 현대적 | R34: 실내 | V34: 개업 36년 전통 문구. 룸·단체석 | W34: Claude(웹 수집) | X34: 2026-10-21 | Y34: https://v.daum.net/v/zCXt4I5rbs | Z34: 초안(웹 수집). 현장 미확인 / 추정 칸: 머무는 시간·1인 지출·태그·지역 / 영업시간 참고: 페이지 표기가 불명확('12~12시', 오타로 보임). 12시 시작 / 브레이크타임 15:00-18:00 / 지출 추정 불가(메뉴 가격 없음) - 직접 입력
A35: store_033 | B35: 커볶(커피볶는집) | C35: 카페·디저트 | D35: 동구 산수동 | E35: 광주 동구 지호로 161-7 | H35: 11:00 | I35: 22:00 | K35: 60 | M35: 무등산 구름 커피 등(가격 없음) | N35: 카페 | P35: 카페·디저트 | Q35: 현대적 | R35: 실내 | S35: 오전, 오후, 저녁 | V35: 개업 2006. 주말 A-ZONE 3인 이상·사전예약 | W35: Claude(웹 수집) | X35: 2026-10-21 | Y35: https://v.daum.net/v/zCXt4I5rbs | Z35: 초안(웹 수집). 현장 미확인 / 추정 칸: 머무는 시간·1인 지출·태그·지역 / 지출 추정 불가(메뉴 가격 없음) - 직접 입력
A36: store_034 | B36: 육층집 | C36: 식당 | D36: 동구 광산동 | E36: 광주광역시 동구 문화전당로35번길 16-4 오렌지타운 6층 | H36: 17:00 | I36: 24:30 | K36: 80 | L36: 10500 | M36: 숙성생삼겹살200g 17,000 / 숙성생목살200g 17,000 / 벌집껍데기 4,000 | N36: 삼겹살 | P36: 식사 | Q36: 현대적 | R36: 실내 | S36: 오후, 저녁, 밤 | V36: 초벌되어 나옴 | W36: Claude(웹 수집) | X36: 2026-10-21 | Y36: https://www.diningcode.com/profile.php?rid=PFkPFKCeK6C0 | Z36: 초안(웹 수집). 현장 미확인 / 추정 칸: 머무는 시간·1인 지출·태그·지역 / 영업시간 참고: 요일별로 다름 / 라스트오더 23:30-00:00
A37: store_035 | B37: 구수숯불갈비 | C37: 식당 | D37: 동구 동명동 | E37: 광주광역시 동구 필문대로191번길 15-10 | H37: 11:00 | I37: 22:00 | K37: 80 | L37: 18000 | M37: 생소갈비220g 49,000 / 돼지갈비230g 18,000 / 삼겹살150g 18,000 | N37: 돼지갈비 | P37: 식사 | Q37: 현대적 | R37: 실내 | S37: 오전, 오후, 저녁 | V37: 무료주차,룸식 | W37: Claude(웹 수집) | X37: 2026-10-21 | Y37: https://www.diningcode.com/profile.php?rid=fxpHPLxNfiSF | Z37: 초안(웹 수집). 현장 미확인 / 추정 칸: 머무는 시간·1인 지출·태그·지역 / 브레이크타임 15:00-16:30 / 라스트오더 20:40 / 휴무 확인 필요(매달 1,3째 화요일)
A38: store_036 | B38: 이씨네 푸줏간 본점 | C38: 식당 | D38: 동구 동명동 | E38: 광주광역시 동구 동명로 48 | H38: 16:30 | I38: 23:00 | K38: 80 | L38: 16500 | M38: 한근세트 59,000 / 생갈비 18,000 / 통오겹살 15,000 | N38: 고깃집 | P38: 식사 | Q38: 현대적 | R38: 실내 | S38: 오후, 저녁, 밤 | W38: Claude(웹 수집) | X38: 2026-10-21 | Y38: https://www.diningcode.com/profile.php?rid=YLyYPMFqKe5R | Z38: 초안(웹 수집). 현장 미확인 / 추정 칸: 머무는 시간·1인 지출·태그·지역 / 라스트오더 22:00
A39: store_037 | B39: 후동이 소금구이 | C39: 식당 | D39: 동구 동명동 | E39: 광주광역시 동구 동명로 15 1층 | H39: 17:00 | I39: 24:50 | K39: 80 | L39: 9500 | M39: 소금구이180g 11,900 / 생삼겹살180g 12,900 / 김치찌개 7,000 | N39: 고깃집 | P39: 식사 | Q39: 현대적 | R39: 실내 | S39: 오후, 저녁, 밤 | V39: 직원이 구워줌 | W39: Claude(웹 수집) | X39: 2026-10-21 | Y39: https://www.diningcode.com/profile.php?rid=ICZnPzYLPBSI | Z39: 초안(웹 수집). 현장 미확인 / 추정 칸: 머무는 시간·1인 지출·태그·지역 / 영업시간 참고: 금·토 02:50, 일 23:50까지 / 휴무 확인 필요(매달 1,3째 일요일(블로그))
A40: store_038 | B40: 미분당 광주동명점 | C40: 식당 | D40: 동구 동명동 | E40: 광주광역시 동구 제봉로110번길 3 1층 | H40: 11:00 | I40: 21:00 | K40: 40 | L40: 11000 | M40: 차돌박이 쌀국수 10,000 / 양지 쌀국수 11,500 / 차돌양지 쌀국수 12,500 | N40: 쌀국수 | P40: 식사 | Q40: 현대적 | R40: 실내 | S40: 오전, 오후, 저녁 | V40: 혼밥,무료주차 | W40: Claude(웹 수집) | X40: 2026-10-21 | Y40: https://www.diningcode.com/profile.php?rid=JuqmKm3Nl8or | Z40: 초안(웹 수집). 현장 미확인 / 추정 칸: 머무는 시간·1인 지출·태그·지역 / 브레이크타임 15:00-17:00 / 라스트오더 14:30,20:30
...

Sheet 체크리스트
A1: 가게 id | B1: 가게 이름 | C1: ★채점자 | D1: [광주다움] 5·18 등 광주 근현대사 사건의 현장이다 | E1: [광주다움] 지정·등록 문화유산이거나 근대건축물이다 | F1: [광주다움] 광주 고유의 음식·예술·인물과 직접 관련된다 | G1: [광주다움] 같은 자리에서 30년 이상 운영했다 | H1: [상권 연계성] 프랜차이즈나 대기업 직영이 아니다 (공공시설은 체크) | I1: [상권 연계성] 전통시장·상점가·골목상권 구역 안에 있다 | J1: [상권 연계성] 반경 300m 안에 소상공인 점포가 많다 (기준 점포 수는 데이터 수집 후 확정) | K1: [체류 유도성] 앉아서 쉴 수 있는 자리(좌석·벤치)가 있다 | L1: 근거 (링크·사진 파일명·메모)
A2: 가게정보의 id 고르기 | B2: 자동 | C2: 본인 이름 | D2: 확인 방법: 5·18 사적지 목록 등 공식 지정 여부 | E2: 확인 방법: 국가유산청 문화유산 검색 | F2: 확인 방법: 광주시 대표 음식·음식 거리 지정, 공식 소개 자료 | G2: 확인 방법: 개관·개업 연도 (공식 소개, 인허가 자료) | H2: 확인 방법: 가맹사업 정보공개서 조회, 상호 검색 | I2: 확인 방법: 소상공인시장진흥공단 전통시장·상점가 자료 | J2: 확인 방법: 소상공인 상가(상권)정보 공공데이터 | K2: 확인 방법: 현장 확인 (사진) | L2: O/X를 정한 근거. 항목 이름과 함께 적기
B3: =IF(A3="","",IFERROR(INDEX(가게정보!$B$3:$B$122,MATCH(A3,가게정보!$A$3:$A$122,0)),"(id를 확인하세요)"))
B4: =IF(A4="","",IFERROR(INDEX(가게정보!$B$3:$B$122,MATCH(A4,가게정보!$A$3:$A$122,0)),"(id를 확인하세요)"))
B5: =IF(A5="","",IFERROR(INDEX(가게정보!$B$3:$B$122,MATCH(A5,가게정보!$A$3:$A$122,0)),"(id를 확인하세요)"))
B6: =IF(A6="","",IFERROR(INDEX(가게정보!$B$3:$B$122,MATCH(A6,가게정보!$A$3:$A$122,0)),"(id를 확인하세요)"))
B7: =IF(A7="","",IFERROR(INDEX(가게정보!$B$3:$B$122,MATCH(A7,가게정보!$A$3:$A$122,0)),"(id를 확인하세요)"))
B8: =IF(A8="","",IFERROR(INDEX(가게정보!$B$3:$B$122,MATCH(A8,가게정보!$A$3:$A$122,0)),"(id를 확인하세요)"))
B9: =IF(A9="","",IFERROR(INDEX(가게정보!$B$3:$B$122,MATCH(A9,가게정보!$A$3:$A$122,0)),"(id를 확인하세요)"))
B10: =IF(A10="","",IFERROR(INDEX(가게정보!$B$3:$B$122,MATCH(A10,가게정보!$A$3:$A$122,0)),"(id를 확인하세요)"))
B11: =IF(A11="","",IFERROR(INDEX(가게정보!$B$3:$B$122,MATCH(A11,가게정보!$A$3:$A$122,0)),"(id를 확인하세요)"))
B12: =IF(A12="","",IFERROR(INDEX(가게정보!$B$3:$B$122,MATCH(A12,가게정보!$A$3:$A$122,0)),"(id를 확인하세요)"))
B13: =IF(A13="","",IFERROR(INDEX(가게정보!$B$3:$B$122,MATCH(A13,가게정보!$A$3:$A$122,0)),"(id를 확인하세요)"))
B14: =IF(A14="","",IFERROR(INDEX(가게정보!$B$3:$B$122,MATCH(A14,가게정보!$A$3:$A$122,0)),"(id를 확인하세요)"))
... B302: =IF(A302="","",IFERROR(INDEX(가게정보!$B$3:$B$122,MATCH(A302,가게정보!$A$3:$A$122,0)),"(id를 확인하세요)"))

Sheet 작성 예시
A1: 예시입니다 (가상의 가게). 형식만 참고하세요. 이 시트의 내용은 데이터로 쓰이지 않습니다.
A2: id (수정 금지) | B2: ★가게 이름 | C2: ★유형 | D2: ★지역 | E2: ★도로명 주소 | F2: 위도 | G2: 경도 | H2: ★여는 시각 | I2: ★닫는 시각 | J2: 휴무 요일 | K2: ★머무는 시간(분) | L2: ★1인 예상 지출(원) | M2: 대표 메뉴·가격 [참고] | N2: 음식 종류 [참고] | O2: 식사 시간대 [참고] | P2: ★할 거리 | Q2: ★분위기 | R2: ★공간 | S2: 어울리는 시간 | T2: 어울리는 동행 | U2: 별칭 | V2: 한줄 소개 | W2: 조사자 | X2: 조사일 | Y2: 정보 출처 (링크·날짜) | Z2: 메모
A3: store_001 | B3: (예시) ○○ 국밥 | C3: 식당 | D3: 동구 동명동 | E3: 광주 동구 ○○로 12 (예시) | H3: 11:00 | I3: 21:00 | J3: 월 | K3: 50 | L3: 9000 | M3: 순대국밥 9,000 / 수육 25,000 | N3: 한식 | O3: 점심·저녁 모두 | P3: 식사 | Q3: 서민적, 활기찬 | R3: 실내 | S3: 오후, 저녁 | T3: 혼자, 친구, 가족 | U3: ○○국밥집 | V3: 2008년 개업. 대표 메뉴는 순대국밥. | W3: 홍길동 | X3: 2026-10-20 | Y3: 현장 확인(2026-10-20), 가게 인스타 소개글
A4: store_002 | B4: (예시) △△ 커피 | C4: 카페·디저트 | D4: 동구 동명동 | E4: 광주 동구 △△길 5 (예시) | H4: 10:00 | I4: 22:00 | K4: 70 | L4: 6500 | M4: 아메리카노 4,500 / 수제 케이크 6,500 | N4: 카페·디저트 | O4: 해당 없음 | P4: 카페·디저트, 사진, 휴식 | Q4: 감성적, 조용한 | R4: 실내 | S4: 오후, 저녁 | T4: 혼자, 친구, 연인 | V4: 한옥을 고쳐 만든 카페. 마당 좌석이 있음. | W4: 홍길동 | X4: 2026-10-20 | Y4: 현장 확인(2026-10-20)
A6: 체크리스트 시트 예시
A7: store_001 | B7: (예시) ○○ 국밥 | C7: 홍길동 | D7: X | E7: X | F7: O | G7: X | H7: O | I7: O | J7: O | K7: O | L7: 광주 대표 음식 국밥 소개 자료 링크(예시), 시장 구역 지도 캡처 파일명(예시), 좌석 사진 파일명(예시)

Sheet 목록
A1: 유형 | B1: 시스템 코드 | C1: 공간 | D1: O/X | E1: 음식 종류 [참고] | F1: 식사 시간대 [참고] | G1: 할 거리 (여러 개 가능) | H1: 분위기 (여러 개 가능) | I1: 어울리는 시간 (여러 개 가능) | J1: 어울리는 동행 (여러 개 가능)
A2: 식당 | B2: food | C2: 실내 | D2: O | E2: 한식 | F2: 점심 | G2: 사진 | H2: 조용한 | I2: 오전 | J2: 혼자
A3: 카페·디저트 | B3: cafe | C3: 실외 | D3: X | E3: 중식 | F3: 저녁 | G3: 산책 | H3: 활기찬 | I3: 오후 | J3: 친구
A4: 전통시장 | B4: market | C4: 실내외 | E4: 일식 | F4: 점심·저녁 모두 | G4: 전시 관람 | H4: 레트로 | I4: 저녁 | J4: 연인
A5: 상점가 | B5: shop | E5: 양식 | F5: 해당 없음 | G5: 공연·영화 | H5: 현대적 | I5: 밤 | J5: 가족
A6: 명소·산책 | B6: sight | E6: 분식 | G6: 역사 탐방 | H6: 전통적 | J6: 아이 동반
A7: 문화·전시 | B7: culture | E7: 카페·디저트 | G7: 건축 구경 | H7: 예술적
A8: 야간 콘텐츠 | B8: night | E8: 주점 | G8: 식사 | H8: 감성적
E9: 기타 | G9: 길거리 음식 | H9: 자연 속
G10: 카페·디저트 | H10: 서민적
G11: 술
G12: 쇼핑
G13: 시장 구경
G14: 공방 체험
G15: 야경
G16: 휴식
A18: 할 거리·분위기·시간·동행은 data/tags.json 과 같은 값입니다. 목록에 없는 말은 쓰지 마세요.
